# 飞书手动同步功能修复说明

## 问题描述

在测试过程中发现，飞书同步功能在测试脚本中能够正常工作，但是通过UI界面进行手动同步时却失败。用户反馈："在做测试的时候就可以同步过去，但是手动从同步就是不能同步过去"。

## 问题分析

通过代码审查发现，问题出现在UI界面的手动同步功能调用了一个不存在的方法：

### 错误的调用
在 `src/ui/main_window.py` 文件的 `sync_to_feishu()` 方法中：
```python
# 错误的调用 - 方法不存在
success_count, total_count = self.feishu_sync.sync_batch_records(unsynced_records)
```

### 实际存在的方法
在 `src/utils/feishu_sync.py` 文件中，实际存在的批量同步方法是：
```python
def sync_all_records_to_feishu(self) -> Dict[str, int]:
    """
    将所有未同步的记录同步到飞书
    
    Returns:
        Dict[str, int]: 同步结果统计 {'success': int, 'failed': int, 'skipped': int}
    """
```

## 问题原因

1. **方法名不匹配**：UI调用的 `sync_batch_records()` 方法在 `FeishuSyncService` 类中不存在
2. **参数传递错误**：不存在的方法期望接收 `unsynced_records` 参数，但实际方法会自动获取未同步记录
3. **返回值格式不同**：UI期望返回 `(success_count, total_count)` 元组，但实际方法返回字典格式

## 解决方案

修改 `src/ui/main_window.py` 文件中的手动同步代码：

### 修复前
```python
# 批量同步
success_count, total_count = self.feishu_sync.sync_batch_records(unsynced_records)

# 更新UI
self.root.after(0, lambda: self._sync_complete_callback(success_count, total_count))
```

### 修复后
```python
# 批量同步
sync_result = self.feishu_sync.sync_all_records_to_feishu()
success_count = sync_result['success']
total_count = success_count + sync_result['failed']

# 更新UI
self.root.after(0, lambda: self._sync_complete_callback(success_count, total_count))
```

## 修复验证

创建了测试脚本 `test_manual_sync_fix.py` 来验证修复效果：

### 测试结果
```
测试修复后的手动同步功能
============================================================

1. 检查飞书配置...
✅ 飞书功能已启用

2. 测试飞书连接...
✅ 飞书连接测试成功

3. 获取未同步的记录...
找到 1 条未同步记录

4. 测试修复后的手动同步方法...
调用 sync_all_records_to_feishu() 方法...

同步结果:
   成功: 1
   失败: 0
   总计: 1
✅ 手动同步功能修复成功！

5. 验证同步结果...
剩余未同步记录: 0 条
✅ 成功同步了 1 条记录
```

## 技术细节

### 测试脚本 vs 手动同步的差异

1. **测试脚本**：直接调用 `sync_record_to_feishu(sequence_id)` 方法同步单条记录
2. **手动同步**：调用批量同步方法处理所有未同步记录
3. **自动同步**：在分析完成后自动调用 `sync_single_record()` 方法

### 方法调用链

- **测试脚本**：`test_sync_with_logs.py` → `sync_record_to_feishu()` ✅
- **手动同步**：`main_window.py` → `sync_batch_records()` ❌ (方法不存在)
- **修复后**：`main_window.py` → `sync_all_records_to_feishu()` ✅

## 预防措施

1. **代码审查**：在修改UI调用时，确保被调用的方法确实存在
2. **单元测试**：为UI组件创建单元测试，验证方法调用的正确性
3. **集成测试**：定期运行完整的功能测试，确保各个组件协调工作
4. **文档同步**：及时更新API文档，确保方法签名和返回值格式的一致性

## 相关文件

- `src/ui/main_window.py` - 主窗口UI，包含手动同步功能
- `src/utils/feishu_sync.py` - 飞书同步服务类
- `test_manual_sync_fix.py` - 修复验证测试脚本
- `test_sync_with_logs.py` - 原始测试脚本（工作正常）

## 总结

这个问题是一个典型的方法调用错误，由于UI代码调用了不存在的方法导致手动同步功能失败。通过修正方法调用和参数处理，成功恢复了手动同步功能。测试脚本能够正常工作是因为它直接调用了正确的底层方法，而手动同步使用了错误的批量处理方法调用。

修复后，手动同步功能与测试脚本具有相同的可靠性，用户可以正常使用UI界面进行飞书数据同步操作。